<?xml version="1.0" ?>
<!-- =================================================================================== -->
<!-- |    This document was autogenerated by xacro from /home/lkx/Desktop/tita_ros2/install/locomotion_bringup/share/locomotion_bringup/urdf/tita.urdf.xacro | -->
<!-- |    EDITING THIS FILE BY HAND IS NOT RECOMMENDED                                 | -->
<!-- =================================================================================== -->
<robot name="tita_ros2_control">
  <material name="black">
    <color rgba="0.19607843137254902 0.19607843137254902 0.19607843137254902 1.0"/>
  </material>
  <material name="blue">
    <color rgba="0.0 0.0 0.8 1.0"/>
  </material>
  <material name="green">
    <color rgba="0.0 0.8 0.0 1.0"/>
  </material>
  <material name="grey">
    <color rgba="0.2 0.2 0.2 1.0"/>
  </material>
  <material name="silver">
    <color rgba="0.9137254901960784 0.9137254901960784 0.8470588235294118 1.0"/>
  </material>
  <material name="orange">
    <color rgba="1.0 0.4235294117647059 0.0392156862745098 1.0"/>
  </material>
  <material name="brown">
    <color rgba="0.8705882352941177 0.8117647058823529 0.7647058823529411 1.0"/>
  </material>
  <material name="red">
    <color rgba="0.8 0.0 0.0 1.0"/>
  </material>
  <material name="white">
    <color rgba="1.0 1.0 1.0 1.0"/>
  </material>
  <link name="base_link">
    <inertial>
      <!-- <origin rpy="0 0 0" xyz="0.020452 3.5457E-06 0.01871"/> -->
      <!-- <origin rpy="0 0 0" xyz="0.04 0.0 0.0"/> -->
      <origin rpy="0 0 0" xyz="-0.01256 -0.0001374 0.029873"/>
      <!-- <mass value="13.2"/> -->
      <!-- <mass value="17.328"/> -->
      <mass value="18.96"/>
      <!--inertia ixx="0.061855" ixy="-2.6029E-05" ixz="0.00081082" iyy="0.036934" iyz="-1.7269E-05" izz="0.071232"/-->
      <!-- <inertia ixx="0.182084475" ixy="-2.6029E-05" ixz="0.00081082" iyy="0.3711" iyz="-1.7269E-05" izz="0.448929922" /> -->
      <!-- <inertia ixx="0.1387" ixy="-2.6029E-05" ixz="0.00081082" iyy="0.2827" iyz="-1.7269E-05" izz="0.3420" /> -->
      <!-- <inertia ixx="0.13871" ixy="-2.6029E-05" ixz="0.00081082" iyy="0.31471" iyz="-1.7269E-05" izz="0.374" /> -->
      <!-- <inertia ixx="0.13871" ixy="0.0" ixz="0.0" iyy="0.31471" iyz="0.0" izz="0.374" /> -->
      <inertia ixx="0.3196735" ixy="0" ixz="0" iyy="0.5268257" iyz="0" izz="0.7383482" />
    </inertial>
    <visual>
      <!-- <origin rpy="0 0 0" xyz="0 0 0.017"/>
      <geometry>
        <box size="0.47 0.3 0.19"/>
      </geometry> -->
      <!-- <material name="black"/> -->
      <origin rpy="0 0 0" xyz="0 0 0"/>
      <geometry>
        <mesh filename="../meshes/base_link.STL"/>
      </geometry>

    </visual>
    <collision>
      <!-- <origin rpy="0 0 0" xyz="0 0 0.017"/> -->
      <origin rpy="0 0 0" xyz="0 0 0"/>
      <geometry>
        <!-- <box size="0.47 0.3 0.19"/> -->
        <!-- <box size="0.50 0.3 0.19" /> -->
        <mesh filename="../meshes/base_link.STL"/>
        <!-- <box size="0.547 0.41 0.185" /> -->
      </geometry>
    </collision>
  </link>
  <link name="spad">
    </link>
  <joint name="spad" type="fixed">
    <origin rpy="2.199 0 1.5708" xyz="0.24052 -0.0019 0.064455"/>
    <parent link="base_link"/>
    <child link="spad"/>
    <axis xyz="0 0 0"/>
  </joint>
  <link name="spad1">
    </link>
  <joint name="spad1" type="fixed">
    <origin rpy="2.632 0 1.5708" xyz="0.21953 -0.0019 -0.030142"/>
    <parent link="base_link"/>
    <child link="spad1"/>
    <axis xyz="0 0 0"/>
  </joint>
  <link name="left_camera">
    </link>
  <joint name="left_camera" type="fixed">
    <origin rpy="1.5708 0 1.5708" xyz="0.23416 0.075 0.04036"/>
    <parent link="base_link"/>
    <child link="left_camera"/>
    <axis xyz="0 0 0"/>
  </joint>
  <link name="ch201">
    </link>
  <joint name="ch201" type="fixed">
    <origin rpy="1.1693 0 1.5708" xyz="0.23782 0 0.018636"/>
    <parent link="base_link"/>
    <child link="ch201"/>
    <axis xyz="0 0 0"/>
  </joint>
  <link name="right_camara">
    </link>
  <joint name="right_camera" type="fixed">
    <origin rpy="1.5708 0 1.5708" xyz="0.23416 -0.075001 0.04036"/>
    <parent link="base_link"/>
    <child link="right_camara"/>
    <axis xyz="0 0 0"/>
  </joint>
  <link name="left_leg_1">
    <inertial>
      <!-- <origin rpy="0 0 0" xyz="0.0016025 5.0253E-05 0.000638"/> -->
      <origin rpy="0 0 0" xyz="-0.0095966 5.1802E-05 -0.0028195"/>
      <!-- <mass value="2.064"/> -->
      <mass value="4.65"/>
      <!-- <inertia ixx="0.0043044" ixy="-1.3538E-07" ixz="8.054E-05" iyy="0.0029982" iyz="-1.5446E-06" izz="0.0022703"/> -->
      <!-- <inertia ixx="0.004096" ixy="-1.3538E-07" ixz="8.054E-05" iyy="0.003768" iyz="-1.5446E-06" izz="0.003768" /> -->
      <inertia ixx="0.00908203125" ixy="0" ixz="0" iyy="0.01567475" iyz="0" izz="0.228956" />
    </inertial>
    <visual>
      <origin rpy="0 0 0" xyz="0 0 0"/>
      <geometry>
         <mesh filename="../meshes/L_1.STL"/>
      </geometry>
      <!-- <material name="black"/> -->
    </visual>
  </link>
  <joint name="joint_left_leg_1" type="revolute">
    <!-- <origin rpy="1.5708 0 1.5708" xyz="0 0.0895 0"/> -->
    <origin rpy="1.5776 -2.4621E-05 1.5708" xyz="0 0.131 0"/>
    <parent link="base_link"/>
    <child link="left_leg_1"/>
    <axis xyz="0 0 1"/>
    <!--limit effort="60" lower="-0.785398" upper="0.785398" velocity="25"/-->
    <limit effort="60" lower="-1.5708" upper="1.5708" velocity="15"/>
  </joint>
  <link name="left_leg_2">
    <inertial>
      <!-- <origin rpy="0 0 0" xyz="0.021763 0.0019069 -0.027868"/> -->
      <origin rpy="0 0 0" xyz="0.099982 0.0028766 -0.0045531"/>
      <!-- <mass value="3.0984"/> -->
      <mass value="3.14"/>
      <!-- <inertia ixx="0.0029784" ixy="-9.6332E-05" ixz="7.878E-05" iyy="0.0064836" iyz="4.3691E-06" izz="0.0088353"/> -->
      <!-- <inertia ixx="0.006793" ixy="-9.6332E-05" ixz="7.878E-05" iyy="0.006793" iyz="4.3691E-06" izz="0.006146" /> -->
      <inertia ixx="0.0041866667" ixy="0" ixz="0" iyy="0.1214306667" iyz="0" izz="0.1247626667" />
    </inertial>
    <visual>
      <origin rpy="0 0 0" xyz="0 0 0"/>
      <geometry>
         <mesh filename="../meshes/L_2.STL"/>
      </geometry>
    </visual>
    <!-- <visual>
      <origin rpy="0 0 -0.131" xyz="0.1 0.021 -0.002"/>
      <geometry>
        <box size="0.2 0.09 0.05"/>
      </geometry>
      <material name="black"/>
    </visual> -->
    <!-- <collision>
      <origin rpy="0 0 -0.131" xyz="0.1 0.021 -0.002"/>
      <geometry>
        <box size="0.2 0.09 0.05"/>
      </geometry>
    </collision> -->
    <!-- <collision>
      <origin rpy="0 0 0" xyz="0 0 0"/>
      <geometry>
        <box size="0.34 0.125 0.04"/>
      </geometry>
    </collision> -->
  </link>
  <joint name="joint_left_leg_2" type="revolute">
    <!-- <origin rpy="-1.5708 0 -1.5708" xyz="0.1426 0 0"/> -->
    <origin rpy="-1.5708 -0.086165 -1.5708" xyz="0.1264 0 0"/>
    <parent link="left_leg_1"/>
    <child link="left_leg_2"/>
    <axis xyz="0 0 1"/>
    <!--limit effort="60" lower="-1.919862" upper="3.490659" velocity="25"/-->
    <limit effort="60" lower="-1.919" upper="2.618" velocity="15"/>
  </joint>
  <link name="left_leg_3">
    <inertial>
      <!-- <origin rpy="0 0 0" xyz="0.095348 0.011698 0.001838"/> -->
      <origin rpy="0 0 0" xyz="0.17019 -0.00040896 0.016709"/>
      <!-- <mass value="0.57244"/> -->
      <mass value="1.59"/>
      <!-- <inertia ixx="0.00030595" ixy="0.00035537" ixz="-0.00011764" iyy="0.0032009" iyz="1.129E-05" izz="0.0034209"/> -->
      <!-- <inertia ixx="0.006077" ixy="0.00035537" ixz="-0.00011764" iyy="0.002028" iyz="1.129E-05" izz="0.002142" /> -->
      <inertia ixx="0.00070225" ixy="0" ixz="0" iyy="0.041605" iyz="0" izz="0.04220125" />
    </inertial>
    <visual>
      <origin rpy="0 0 0" xyz="0 0 0"/>
      <geometry>
         <mesh filename="../meshes/L_3.STL"/>
      </geometry>
      <!-- <origin rpy="0 0 -0.131" xyz="0.1 0.021 -0.002"/>
      <geometry>
        <box size="0.2 0.07 0.05"/>
      </geometry>
      <material name="black"/> -->
    </visual>
    <collision>
      <origin rpy="0 0 0" xyz="0 0 0"/>
      <geometry>
        <!-- <box size="0.2 0.07 0.05"/> -->
        <!-- <box size="0.25 0.07 0.05" /> -->
        <!-- <mesh filename="../meshes/L_3.STL"/> -->
        <box size="0.28 0.07 0.02" />
      </geometry>
    </collision>
  </link>
  <joint name="joint_left_leg_3" type="revolute">
    <!-- <origin rpy="0 0 0" xyz="0.2 0 0"/> -->
    <origin rpy="0 0 0.072636" xyz="0.25 0 0"/>
    <parent link="left_leg_2"/>
    <child link="left_leg_3"/>
    <axis xyz="0 0 1"/>
    <!--limit effort="60" lower="-2.670354" upper="-0.698132" velocity="25"/-->
    <!-- <limit effort="60" lower="-2.670354" upper="-0.698132" velocity="15"/> -->
    <!-- <limit effort="60" lower="-2.094" upper="0.0" velocity="15"/> -->
    <limit effort="60" lower="-2.3562" upper="-0.7854" velocity="15"/>
  </joint>
  <link name="left_leg_4">
    <inertial>
      <!-- <origin rpy="0 0 0" xyz="-2.267E-06 -1.6471E-06 -0.00095616"/> -->
      <origin rpy="0 0 0" xyz="-6.5652E-09 3.4765E-06 -0.00023191"/>
      <!-- <mass value="1.5094"/> -->
      <mass value="1.54"/>
      <!-- <inertia ixx="0.0035466" ixy="6.9816E-06" ixz="-2.3224E-07" iyy="0.0035053" iyz="-1.7712E-08" izz="0.0069049"/> -->
      <!-- <inertia ixx="0.003001" ixy="6.9816E-06" ixz="-2.3224E-07" iyy="0.003001" iyz="-1.7712E-08" izz="0.005713" /> -->
      <inertia ixx="0.0035805" ixy="0" ixz="0" iyy="0.0035805" iyz="0" izz="0.006237" />    
    </inertial>
    <visual>
      <origin rpy="0 0 0" xyz="0 0 0"/>
      <geometry>
         <mesh filename="../meshes/L_4.STL"/>
      </geometry>
      <!-- <origin rpy="0 0 0" xyz="0 0 0"/>
      <geometry>
        <cylinder length="0.034" radius="0.0925"/>
      </geometry>
      <material name="black"/> -->
    </visual>
    <collision>
      <origin rpy="0 0 0" xyz="0 0 0"/>
      <geometry>
        <!-- <cylinder length="0.034" radius="0.0925"/> -->
        <!-- <cylinder radius="0.087" length="0.034" /> -->
        <!-- <mesh filename="../meshes/L_4.STL" /> -->
        <cylinder radius="0.09" length="0.03" />
      </geometry>
    </collision>
  </link>
  <joint name="joint_left_leg_4" type="revolute">
    <!-- <origin rpy="0 0 0" xyz="0.2 0 0.0514"/> -->
    <origin rpy="0 0 -1.5573" xyz="0.22 0 0.0581"/>
    <parent link="left_leg_3"/>
    <child link="left_leg_4"/>
    <axis xyz="0 0 1"/>
    <limit effort="7" lower="-999999" upper="999999" velocity="20"/>
  </joint>
  <link name="right_leg_1">
    <inertial>
      <!-- <origin rpy="0 0 0" xyz="-0.0016025 5.0253E-05 0.00063801"/> -->
      <origin rpy="0 0 0" xyz="0.0096538 5.0707E-05 -0.0022585"/>
      <!-- <mass value="2.064"/> -->
      <mass value="4.65"/>
      <!-- <inertia ixx="0.0043044" ixy="1.3538E-07" ixz="-8.054E-05" iyy="0.0029982" iyz="-1.5359E-06" izz="0.0022703"/> -->       
      <!-- <inertia ixx="0.004096" ixy="-1.3538E-07" ixz="8.054E-05" iyy="0.003768" iyz="-1.5446E-06" izz="0.003768" /> -->
      <!-- <inertia ixx="0.004096" ixy="1.3538E-07" ixz="-8.054E-05" iyy="0.003768" iyz="-1.5446E-06" izz="0.003768" /> -->
      <inertia ixx="0.00908203125" ixy="0" ixz="0" iyy="0.01567475" iyz="0" izz="0.228956" />
    </inertial>
    <visual>
      <origin rpy="0 0 0" xyz="0 0 0"/>
      <geometry>
         <mesh filename="../meshes/R_1.STL"/>
      </geometry>
      <!-- <material name="black"/> -->
    </visual>
  </link>
  <joint name="joint_right_leg_1" type="revolute">
    <!-- <origin rpy="1.5708 0 1.5708" xyz="0 -0.0895 0"/> -->
    <origin rpy="1.5776 -2.4621E-05 1.5708" xyz="0 -0.131 -1.2901E-05"/>
    <parent link="base_link"/>
    <child link="right_leg_1"/>
    <axis xyz="0 0 -1"/>
    <!--limit effort="60" lower="-0.785398" upper="0.785398" velocity="25"/-->
    <!-- <limit effort="60" lower="-0.785398" upper="0.785398" velocity="15"/> -->
    <limit effort="60" lower="-1.5708" upper="1.5708" velocity="15"/>
  </joint>
  <link name="right_leg_2">
    <inertial>
      <!-- <origin rpy="0 0 0" xyz="0.021763 0.0019065 0.027873"/> -->
      <origin rpy="0 0 0" xyz="0.0896183873359781 0.00257781919344477 0.00459219279136702"/>
      <!-- <mass value="3.0984"/> -->
      <mass value="3.14"/>
      <!-- <inertia ixx="0.0029784" ixy="-9.6347E-05" ixz="-7.8776E-05" iyy="0.0064836" iyz="-4.3711E-06" izz="0.0088353"/> -->
      <!-- <inertia ixx="0.006793" ixy="-9.6332E-05" ixz="7.878E-05" iyy="0.006793" iyz="4.3691E-06" izz="0.006146" /> -->
      <!-- <inertia ixx="0.006793" ixy="-9.6332E-05" ixz="-7.878E-05" iyy="0.006793" iyz="-4.3691E-06" izz="0.006146" /> -->
      <inertia ixx="0.0041866667" ixy="0" ixz="0" iyy="0.1214306667" iyz="0" izz="0.1247626667" />
    </inertial>
    <visual>
      <origin rpy="0 0 0" xyz="0 0 0"/>
      <geometry>
         <mesh filename="../meshes/R_2.STL"/>
      </geometry>
    </visual>
    <!-- <visual>
      <origin rpy="0 0 -0.131" xyz="0.1 0.021 -0.002"/>
      <geometry>
        <box size="0.2 0.09 0.05"/>
      </geometry>
      <material name="black"/>
    </visual> -->
    <!-- <collision>
      <origin rpy="0 0 -0.131" xyz="0.1 0.021 -0.002"/>
      <geometry>
        <box size="0.2 0.09 0.05"/>
      </geometry>
    </collision> -->
    <!-- <collision>
      <origin rpy="0 0 0" xyz="0 0 0"/>
      <geometry>
        <box size="0.34 0.125 0.04"/>
      </geometry>
    </collision> -->
  </link>
  <joint name="joint_right_leg_2" type="revolute">
    <!-- <origin rpy="-1.5708 0 -1.5708" xyz="-0.1426 0 0"/> -->
    <origin rpy="-1.5708 -0.086869 -1.5708" xyz="-0.1264 0 0"/>
    <parent link="right_leg_1"/>
    <child link="right_leg_2"/>
    <axis xyz="0 0 1"/>
    <!--limit effort="60" lower="-1.919862" upper="3.490659" velocity="25"/-->
    <!-- <limit effort="60" lower="-1.919862" upper="3.490659" velocity="15"/> -->
    <limit effort="60" lower="-1.919" upper="2.618" velocity="15"/>
  </joint>
  <link name="right_leg_3">
    <inertial>
      <!-- <origin rpy="0 0 0" xyz="0.095348 0.011698 -0.001838"/> -->
      <origin rpy="0 0 0" xyz="0.17012 -0.00044464 -0.016709"/>
      <!-- <mass value="0.57244"/> -->
      <mass value="1.59"/>
      <!-- <inertia ixx="0.00030595" ixy="0.00035537" ixz="0.00011764" iyy="0.0032009" iyz="-1.129E-05" izz="0.0034209"/> -->
      <!-- <inertia ixx="0.006077" ixy="0.00035537" ixz="-0.00011764" iyy="0.002028" iyz="1.129E-05" izz="0.002142" /> -->
      <!-- <inertia ixx="0.006077" ixy="0.00035537" ixz="0.00011764" iyy="0.002028" iyz="-1.129E-05" izz="0.002142" /> -->
      <inertia ixx="0.00070225" ixy="0" ixz="0" iyy="0.041605" iyz="0" izz="0.04220125" />
    </inertial>
    <visual>
      <origin rpy="0 0 0" xyz="0 0 0"/>
      <geometry>
         <mesh filename="../meshes/R_3.STL"/>
      </geometry>
      <!-- <origin rpy="0 0 -0.131" xyz="0.1 0.021 -0.002"/>
      <geometry>
        <box size="0.2 0.07 0.05"/>
      </geometry> -->
      <!-- <material name="black"/> -->
    </visual>
    <collision>
      <!-- <origin rpy="0 0 -0.131" xyz="0.1 0.021 -0.002"/> -->
      <origin rpy="0 0 0" xyz="0 0 0"/>
      <geometry>
        <!-- <box size="0.2 0.07 0.05"/> -->
        <!-- <box size="0.25 0.07 0.05" /> -->
        <!-- <mesh filename="../meshes/R_3.STL"/> -->
        <box size="0.28 0.07 0.02" />
      </geometry>
    </collision>
  </link>
  <joint name="joint_right_leg_3" type="revolute">
    <!-- <origin rpy="0 0 0" xyz="0.2 0 0"/> -->
    <origin rpy="0 0 0.074137" xyz="0.25 0 0"/>
    <parent link="right_leg_2"/>
    <child link="right_leg_3"/>
    <axis xyz="0 0 1"/>
    <!--limit effort="60" lower="-2.670354" upper="-0.698132" velocity="25"/-->
    <!-- <limit effort="60" lower="-2.670354" upper="-0.698132" velocity="15"/> -->
    <limit effort="60" lower="-2.3562" upper="-0.7854" velocity="15"/>
  </joint>
  <link name="right_leg_4">
    <inertial>
      <!-- <origin rpy="0 0 0" xyz="-2.3798E-06 -1.5854E-06 0.00095595"/> -->
      <origin rpy="0 0 0" xyz="-2.4651E-06 -2.4515E-06 0.00058191"/>
      <!-- <mass value="1.5094"/> -->
      <mass value="1.54"/>
      <!-- <inertia ixx="0.0035465" ixy="7.0548E-06" ixz="2.3146E-07" iyy="0.0035052" iyz="1.9287E-08" izz="0.0069047"/> -->
      <!-- <inertia ixx="0.003001" ixy="6.9816E-06" ixz="-2.3224E-07" iyy="0.003001" iyz="-1.7712E-08" izz="0.005713" /> -->
      <!-- <inertia ixx="0.003001" ixy="6.9816E-06" ixz="2.3224E-07" iyy="0.003001" iyz="1.7712E-08" izz="0.005713" /> -->
      <inertia ixx="0.0035805" ixy="0" ixz="0" iyy="0.0035805" iyz="0" izz="0.006237" />
    </inertial>
    <visual>
      <origin rpy="0 0 0" xyz="0 0 0"/>
      <geometry>
         <mesh filename="../meshes/R_4.STL"/>
      </geometry>
      <!-- <origin rpy="0 0 0" xyz="0 0 0"/>
      <geometry>
        <cylinder length="0.034" radius="0.0925"/>
      </geometry>
      <material name="black"/> -->
    </visual>
    <collision>
      <origin rpy="0 0 0" xyz="0 0 0"/>
      <geometry>
        <!-- <cylinder length="0.034" radius="0.0925"/> -->
        <!-- <cylinder radius="0.087" length="0.034" /> -->
        <!-- <mesh filename="../meshes/R_4.STL"/> -->
        <cylinder radius="0.09" length="0.03" />
      </geometry>
    </collision>
  </link>
  <joint name="joint_right_leg_4" type="revolute">
    <!-- <origin rpy="0 0 0" xyz="0.2 0 -0.0514"/> -->
    <origin rpy="0 0 -1.5581" xyz="0.22 0 -0.05845"/>
    <parent link="right_leg_3"/>
    <child link="right_leg_4"/>
    <axis xyz="0 0 1"/>
    <limit effort="7" lower="-999999" upper="999999" velocity="20"/>
  </joint>

  <!-- <link
    name="Radar">
    <inertial>
      <origin
        xyz="0 0 0"
        rpy="0 0 0" />
      <mass
        value="0" />
      <inertia
        ixx="0"
        ixy="0"
        ixz="0"
        iyy="0"
        iyz="0"
        izz="0" />
    </inertial>
    <visual>
      <origin
        xyz="0 0 0"
        rpy="0 0 0" />
      <geometry>
        <mesh
          filename="../meshes/Radar.STL" />
      </geometry>
      <material
        name="">
        <color
          rgba="1 1 1 1" />
      </material>
    </visual>
    <collision>
      <origin
        xyz="0 0 0"
        rpy="0 0 0" />
      <geometry>
        <mesh
          filename="../meshes/Radar.STL" />
      </geometry>
    </collision>
    </link>
    <joint
      name="R_J"
      type="revolute">
      <origin
        xyz="0.18706 -1.039E-05 -0.067865"
        rpy="3.1415 0.25504 3.1414" />
      <parent
        link="base_link" />
      <child
        link="Radar" />
      <axis
        xyz="0 0 -1" />
      <limit
        lower="0"
        upper="0"
        effort="0"
        velocity="0" />
    </joint> -->
</robot>
